Workbook

Sheet Data
J2: VLOOKUP (Vertical Lookup) Use case: Look up DeptCode in the main table and return DeptName from the Dept lookup table. =VLOOKUP(D9,Table4[[DeptCode]:[DeptName]],2,FALSE) | K2: XLOOKUP (Vertical Lookup) Use case: Look up DeptCode in the main table and return DeptManager from the Dept lookup table. =XLOOKUP(D8,Table4[DeptCode],Table4[Manager],"Not assigned",0) | L2: DeptCode | M2: DeptName | N2: Manager | O2: CostCenter
L3: SLS | M3: Sales | N3: Anita Verma | O3: 6001
J4: VLOOKUP(D9,TABLE4[[SLS]:[SALES]],2,FALSE) | K4: XLOOKUP(D8,TABLE4[[SLS],Table4[Manager],"Not assigned",0) | L4: HR | M4: Human Resources | N4: Vijay Rao | O4: 6002
L5: IT | M5: Information Technology | N5: Meera Iyer | O5: 6003
A6: EmployeeID | B6: SKU | C6: Name | D6: DeptCode | E6: JoinDate | F6: BirthDate | G6: LastLogin | H6: BaseSalary | I6: PerformanceScore | J6: Dept name | K6: Manager | L6: FIN | M6: Finance | N6: Arun Sharma | O6: 6004
A7: E101 | B7: P100 | C7: John Smith | D7: SLS | E7: 2019-05-10 | F7: 1991-04-15 | G7: 45890.396 | H7: 52000 | I7: 85 | J7: =VLOOKUP(D7,Data!$L$3:$M$6,2,FALSE) -> Sales | K7: {=XLOOKUP(D7,Data!$L$3:$L$6,Data!$N$3:$N$6,"Not assigned",0)} -> Anita Verma
A8: E102 | B8: P101 | C8: Anna Lee | D8: HR | E8: 2018-03-14 | F8: 1988-10-22 | G8: 45891 | H8: 48000 | I8: 90 | J8: =VLOOKUP(D8,Data!$L$3:$M$6,2,FALSE) -> Human Resources | K8: {=XLOOKUP(D8,Data!$L$3:$L$6,Data!$N$3:$N$6,"Not assigned",0)} -> Vijay Rao
A9: E103 | B9: P102 | C9: Raj Kumar | D9: IT | E9: 2020-07-21 | F9: 1994-02-11 | G9: 45892 | H9: 60000 | I9: 78 | J9: =VLOOKUP(D9,Data!$L$3:$M$6,2,FALSE) -> Information Technology | K9: {=XLOOKUP(D9,Data!$L$3:$L$6,Data!$N$3:$N$6,"Not assigned",0)} -> Meera Iyer
A10: E104 | B10: P100 | C10: Maria Jose | D10: SLS | E10: 2019-09-18 | F10: 1992-12-02 | G10: 45893 | H10: 55000 | I10: 88 | J10: =VLOOKUP(D10,Data!$L$3:$M$6,2,FALSE) -> Sales | K10: {=XLOOKUP(D10,Data!$L$3:$L$6,Data!$N$3:$N$6,"Not assigned",0)} -> Anita Verma
A11: E105 | B11: P103 | C11: Ahmed Ali | D11: FIN | E11: 2015-01-05 | F11: 1980-05-30 | G11: 45894 | H11: 75000 | I11: 92 | J11: =VLOOKUP(D11,Data!$L$3:$M$6,2,FALSE) -> Finance | K11: {=XLOOKUP(D11,Data!$L$3:$L$6,Data!$N$3:$N$6,"Not assigned",0)} -> Arun Sharma
A12: E106 | B12: P104 | C12: Priya N | D12: IT | E12: 2021-11-23 | F12: 1993-03-19 | G12: 45895 | H12: 62000 | I12: 81 | J12: =VLOOKUP(D12,Data!$L$3:$M$6,2,FALSE) -> Information Technology | K12: {=XLOOKUP(D12,Data!$L$3:$L$6,Data!$N$3:$N$6,"Not assigned",0)} -> Meera Iyer
A13: E107 | B13: P105 | C13: James Wong | D13: SLS | E13: 2017-04-12 | F13: 1987-09-05 | G13: 45896 | H13: 58000 | I13: 86 | J13: =VLOOKUP(D13,Data!$L$3:$M$6,2,FALSE) -> Sales | K13: {=XLOOKUP(D13,Data!$L$3:$L$6,Data!$N$3:$N$6,"Not assigned",0)} -> Anita Verma
A14: E108 | B14: P101 | C14: Chen Wei | D14: HR | E14: 2016-02-20 | F14: 1984-07-17 | G14: 45897 | H14: 50000 | I14: 79 | J14: =VLOOKUP(D14,Data!$L$3:$M$6,2,FALSE) -> Human Resources | K14: {=XLOOKUP(D14,Data!$L$3:$L$6,Data!$N$3:$N$6,"Not assigned",0)} -> Vijay Rao
A15: E109 | B15: P103 | C15: Neha Singh | D15: FIN | E15: 2018-08-30 | F15: 1991-01-27 | G15: 45898 | H15: 72000 | I15: 95 | J15: =VLOOKUP(D15,Data!$L$3:$M$6,2,FALSE) -> Finance | K15: {=XLOOKUP(D15,Data!$L$3:$L$6,Data!$N$3:$N$6,"Not assigned",0)} -> Arun Sharma
A16: E110 | B16: P104 | C16: Peter Pan | D16: IT | E16: 2019-12-11 | F16: 1989-06-14 | G16: 45899 | H16: 61000 | I16: 82 | J16: =VLOOKUP(D16,Data!$L$3:$M$6,2,FALSE) -> Information Technology | K16: {=XLOOKUP(D16,Data!$L$3:$L$6,Data!$N$3:$N$6,"Not assigned",0)} -> Meera Iyer
A17: E111 | B17: P100 | C17: Luis M | D17: SLS | E17: 2020-10-15 | F17: 1992-08-01 | G17: 45900 | H17: 53000 | I17: 88 | J17: =VLOOKUP(D17,Data!$L$3:$M$6,2,FALSE) -> Sales | K17: {=XLOOKUP(D17,Data!$L$3:$L$6,Data!$N$3:$N$6,"Not assigned",0)} -> Anita Verma
A18: E112 | B18: P101 | C18: Sara Khan | D18: HR | E18: 2021-01-25 | F18: 1996-03-08 | G18: 45901 | H18: 47000 | I18: 77 | J18: =VLOOKUP(D18,Data!$L$3:$M$6,2,FALSE) -> Human Resources | K18: {=XLOOKUP(D18,Data!$L$3:$L$6,Data!$N$3:$N$6,"Not assigned",0)} -> Vijay Rao
A19: E113 | B19: P103 | C19: David Lee | D19: FIN | E19: 2014-07-19 | F19: 1981-11-12 | G19: 45902 | H19: 78000 | I19: 91 | J19: =VLOOKUP(D19,Data!$L$3:$M$6,2,FALSE) -> Finance | K19: {=XLOOKUP(D19,Data!$L$3:$L$6,Data!$N$3:$N$6,"Not assigned",0)} -> Arun Sharma
A20: E114 | B20: P102 | C20: Aisha Patel | D20: IT | E20: 2022-03-08 | F20: 1995-09-29 | G20: 45903 | H20: 61000 | I20: 84 | J20: =VLOOKUP(D20,Data!$L$3:$M$6,2,FALSE) -> Information Technology | K20: {=XLOOKUP(D20,Data!$L$3:$L$6,Data!$N$3:$N$6,"Not assigned",0)} -> Meera Iyer | L20: Column1 | M20: A | N20: B | O20: C | P20: D
A21: E115 | B21: P105 | C21: John Deo | D21: SLS | E21: 2019-06-06 | F21: 1993-04-04 | G21: 45904 | H21: 54000 | I21: 87 | J21: =VLOOKUP(D21,Data!$L$3:$M$6,2,FALSE) -> Sales | K21: {=XLOOKUP(D21,Data!$L$3:$L$6,Data!$N$3:$N$6,"Not assigned",0)} -> Anita Verma | L21: BonusPct | M21: 0.12 | N21: 0.08 | O21: 0.05 | P21: 0.02
A22: E116 | B22: P103 | C22: Sneha Roy | D22: FIN | E22: 2018-09-13 | F22: 1990-02-02 | G22: 45905 | H22: 71000 | I22: 89 | J22: =VLOOKUP(D22,Data!$L$3:$M$6,2,FALSE) -> Finance | K22: {=XLOOKUP(D22,Data!$L$3:$L$6,Data!$N$3:$N$6,"Not assigned",0)} -> Arun Sharma
A23: E117 | B23: P101 | C23: Mark Smith | D23: HR | E23: 2020-05-02 | F23: 1986-10-10 | G23: 45906 | H23: 49000 | I23: 80 | J23: =VLOOKUP(D23,Data!$L$3:$M$6,2,FALSE) -> Human Resources | K23: {=XLOOKUP(D23,Data!$L$3:$L$6,Data!$N$3:$N$6,"Not assigned",0)} -> Vijay Rao
A24: E118 | B24: P104 | C24: Li Na | D24: IT | E24: 2017-08-28 | F24: 1988-01-18 | G24: 45907 | H24: 64000 | I24: 93 | J24: =VLOOKUP(D24,Data!$L$3:$M$6,2,FALSE) -> Information Technology | K24: {=XLOOKUP(D24,Data!$L$3:$L$6,Data!$N$3:$N$6,"Not assigned",0)} -> Meera Iyer | L24: HLOOKUP (Horizontal Lookup) Use case: Fetch Bonus % based on Grade (A, B, C, D) using the Bonus table at the bottom. =HLOOKUP([@Grade],Table2[[#All],[A]:[D]],2)
A25: E119 | B25: P100 | C25: Tom Cruise | D25: SLS | E25: 2016-11-22 | F25: 1985-07-07 | G25: 45908 | H25: 56000 | I25: 84 | J25: =VLOOKUP(D25,Data!$L$3:$M$6,2,FALSE) -> Sales | K25: {=XLOOKUP(D25,Data!$L$3:$L$6,Data!$N$3:$N$6,"Not assigned",0)} -> Anita Verma
A26: E120 | B26: P103 | C26: Riya Mehta | D26: FIN | E26: 2015-12-10 | F26: 1987-02-25 | G26: 45909 | H26: 73000 | I26: 90 | J26: =VLOOKUP(D26,Data!$L$3:$M$6,2,FALSE) -> Finance | K26: {=XLOOKUP(D26,Data!$L$3:$L$6,Data!$N$3:$N$6,"Not assigned",0)} -> Arun Sharma
L29: MinScore | M29: Grade | N29: Grade percentage
L30: 0 | M30: D | N30: =HLOOKUP(Data!$M30,Data!$M$20:$P$21,2,FALSE) -> 0.02
L31: 75 | M31: C | N31: =HLOOKUP(Data!$M31,Data!$M$20:$P$21,2,FALSE) -> 0.05
C32: Date and Time functions | L32: 85 | M32: B | N32: =HLOOKUP(Data!$M32,Data!$M$20:$P$21,2,FALSE) -> 0.08
L33: 92 | M33: A | N33: =HLOOKUP(Data!$M33,Data!$M$20:$P$21,2,FALSE) -> 0.12
C34: Today= | D34: today() | E34: =TODAY() -> 45972
C36: Now= | D36: now() | E36: =now() -> 45972.216
C37: year= | D37: year(e24) | E37: =year(E24) -> 2017 | L37: INDEX + MATCH : Returns the value sitting at the intersection of that row and column Syntax:=INDEX(array, row_num, [column_num]) - array => the table or range. -row_num = which row inside the array -column_num => which column inside the array Look up UnitPrice from SKU using Product lookup : | O37: MATCH =MATCH(lookup_value, lookup_array, [match_type]) Finds the position of a value in a column or row.
C38: Month | E38: =month(D39) -> 11
C39: day | D39: =today() -> 45972 | E39: =DAY(E34) -> 11
C40: weekday in number | D40: weekday(E18) | E40: =weekday(E18) -> 2 | F40: 1-mon,2-tue,3-wed,4-thur,5-fri,6-sat,7-sun | H40: weekday(E18)
C41: display weekday name using choose() | D41: CHOOSE(WEEKDAY(E34),"monday""tue","wednesday","thursday","friday") | E41: =CHOOSE(WEEKDAY(E34),"monday""tue","wednesday","thursday","friday") -> thursday | F41: thursday | L41: SKU | M41: ProductName | N41: UnitPrice
C42: tenure in years | J42: {=INDEX(A7:C10,2,3)} -> Anna Lee | L42: P100 | M42: CRM License | N42: 1200
C43: Tenure months remainder | D43: DATEDIF(E8,TODAY(),"yM") | E43: =DATEDIF(E8,TODAY(),"yM") -> 7 | L43: P101 | M43: HRMS License | N43: 900
C44: Age in years | D44: DATEDIF(F2,TODAY(),"Y") | E44: =DATEDIF(F2,TODAY(),"Y") -> 125 | L44: P102 | M44: Dev Tools Suite | N44: 1500
...
